Chaining(continue)
```
promiseWrapper('start task', 'bad', 2000)
  .then(ok=>{
    console.log(ok);
    return "task 1"})
  .then(ok=>{
    console.log(ok);
    return promiseWrapper('', 'happen something wrong', null, 3000)})
  .then(null, bad => { //!!!!catch error(null)/ignore error(without null)
    console.log(bad)
    return 'continued work'})
  .then(ok=>{
    console.log(ok)
    return promiseWrapper('', 'again something happen', null, 3000)})
  .catch(bad=>{
    console.log("general catch: "+bad)})
```